<?xml version="1.0" ?>
<sdf version="1.9">
  <world name="sonoma">
    <physics name="1ms" type="ignore">
      <max_step_size>0.001</max_step_size>
      <real_time_factor>1.0</real_time_factor>
    </physics>

    <plugin filename="gz-sim-physics-system"
      name="gz::sim::systems::Physics">
    </plugin>
    <plugin
      filename="gz-sim-sensors-system"
      name="gz::sim::systems::Sensors">
      <render_engine>ogre2</render_engine>
    </plugin>
    <plugin filename="gz-sim-user-commands-system"
      name="gz::sim::systems::UserCommands">
    </plugin>
    <plugin filename="gz-sim-scene-broadcaster-system"
      name="gz::sim::systems::SceneBroadcaster">
    </plugin>
    <plugin filename="gz-sim-imu-system"
      name="gz::sim::systems::Imu">
    </plugin>
    <plugin filename="gz-sim-navsat-system"
      name="gz::sim::systems::NavSat">
    </plugin>

    <scene>
      <ambient>1.0 1.0 1.0</ambient>
      <background>0.8 0.8 0.8</background>
      <sky></sky>
    </scene>

    <light name="sun" type="directional">
            <cast_shadows>true</cast_shadows>
            <pose>0 0 10 0 0 0</pose>
            <diffuse>0.8 0.8 0.8 1</diffuse>
            <specular>0.8 0.8 0.8 1</specular>
            <attenuation>
                <range>1000</range>
                <constant>0.9</constant>
                <linear>0.01</linear>
                <quadratic>0.001</quadratic>
            </attenuation>
            <direction>-0.5 0.1 -0.9</direction>
        </light>

    <!-- <spherical_coordinates>
      <latitude_deg>-35.363262</latitude_deg>
      <longitude_deg>149.165237</longitude_deg>
      <elevation>584</elevation>
      <heading_deg>0</heading_deg>
      <surface_model>EARTH_WGS84</surface_model>
    </spherical_coordinates> -->

    <spherical_coordinates>
      <latitude_deg>38.16245133</latitude_deg>
      <longitude_deg>-122.45773993</longitude_deg>
      <elevation>0</elevation>
      <heading_deg>0</heading_deg>
      <surface_model>EARTH_WGS84</surface_model>
    </spherical_coordinates>

    <model name="axes">
      <static>1</static>
      <link name="link">
        <visual name="r">
          <cast_shadows>0</cast_shadows>
          <pose>5 0 0.1 0 0 0</pose>
          <geometry>
            <box>
              <size>10 0.01 0.01</size>
            </box>
          </geometry>
          <material>
            <ambient>1 0 0 0.8</ambient>
            <diffuse>1 0 0 0.8</diffuse>
            <emissive>1 0 0 0.8</emissive>
            <specular>0.5 0.5 0.5 0.8</specular>
          </material>
        </visual>
        <visual name="g">
          <cast_shadows>0</cast_shadows>
          <pose>0 5 0.1 0 0 0</pose>
          <geometry>
            <box>
              <size>0.01 10 0.01</size>
            </box>
          </geometry>
          <material>
            <ambient>0 1 0 0.8</ambient>
            <diffuse>0 1 0 0.8</diffuse>
            <emissive>0 1 0 0.8</emissive>
            <specular>0.5 0.5 0.5 0.8</specular>
          </material>
        </visual>
        <visual name="b">
          <cast_shadows>0</cast_shadows>
          <pose>0 0 5.1 0 0 0</pose>
          <geometry>
            <box>
              <size>0.01 0.01 10</size>
            </box>
          </geometry>
          <material>
            <ambient>0 0 1 0.8</ambient>
            <diffuse>0 0 1 0.8</diffuse>
            <emissive>0 0 1 0.8</emissive>
            <specular>0.5 0.5 0.5 0.8</specular>
          </material>
        </visual>
        <sensor name="navsat_sensor" type="navsat">
          <always_on>1</always_on>
          <update_rate>1</update_rate>
        </sensor>
      </link>
    </model>

    <gui fullscreen="0">

      <!-- 3D scene -->
      <plugin filename="GzScene3D" name="3D View">
        <ignition-gui>
          <title>3D View</title>
          <property type="bool" key="showTitleBar">false</property>
          <property type="string" key="state">docked</property>
        </ignition-gui>

        <engine>ogre2</engine>
        <scene>scene</scene>
        <ambient_light>0.4 0.4 0.4</ambient_light>
        <background_color>0.5 0.8 0.95</background_color>
        <!--camera_pose>276.46 -130.36 5.27 0 0.43 -1.24</camera_pose-->
        <camera_follow>
          <target>prius_hybrid</target>
          <p_gain>0.5</p_gain>
          <offset>0.5 5 2</offset>
        </camera_follow>
      </plugin>

      <!-- World control -->
      <plugin filename="WorldControl" name="World control">
        <ignition-gui>
          <title>World control</title>
          <property type="bool" key="showTitleBar">false</property>
          <property type="bool" key="resizable">false</property>
          <property type="double" key="height">72</property>
          <property type="double" key="width">121</property>
          <property type="double" key="z">1</property>

          <property type="string" key="state">floating</property>
          <anchors target="3D View">
            <line own="left" target="left"/>
            <line own="bottom" target="bottom"/>
          </anchors>
        </ignition-gui>

        <play_pause>true</play_pause>
        <step>true</step>
        <start_paused>true</start_paused>

      </plugin>

      <!-- World statistics -->
      <plugin filename="WorldStats" name="World stats">
        <ignition-gui>
          <title>World stats</title>
          <property type="bool" key="showTitleBar">false</property>
          <property type="bool" key="resizable">false</property>
          <property type="double" key="height">110</property>
          <property type="double" key="width">290</property>
          <property type="double" key="z">1</property>

          <property type="string" key="state">floating</property>
          <anchors target="3D View">
            <line own="right" target="right"/>
            <line own="bottom" target="bottom"/>
          </anchors>
        </ignition-gui>

        <sim_time>true</sim_time>
        <real_time>true</real_time>
        <real_time_factor>true</real_time_factor>
        <iterations>true</iterations>
      </plugin>

      <plugin filename="ImageDisplay" name="dis">
        <ignition-gui>
          <property key="state" type="string">docked</property>
        </ignition-gui>
        <topic>front_camera</topic>
      </plugin>

      <plugin filename="Teleop" name="Teleop">
        <ignition-gui>
          <property type="string" key="state">docked</property>
        </ignition-gui>
        <topic>/cmd_vel</topic>
      </plugin>
    </gui>
    <include>
    <uri>model://sonoma_raceway</uri>
    </include>

    <!-- Iris with Gimbal - optimized for prius world -->
    <include>
        <uri>model://iris_with_gimbal</uri>
        <!-- <pose degrees="true">273.5 -131.0 30.0 0 0 90</pose> -->
        <pose degrees="true">0 0 32 0 0 90</pose>
    </include>

    <!-- Landing Platform for Iris -->
    <model name="landing_platform">
        <static>true</static>
        <pose>0 0 30.8 0 0 0</pose>
        <link name="platform_link">
            <inertial>
                <mass>100</mass>
                <inertia>
                    <ixx>1.0</ixx>
                    <ixy>0</ixy>
                    <ixz>0</ixz>
                    <iyy>1.0</iyy>
                    <iyz>0</iyz>
                    <izz>1.0</izz>
                </inertia>
            </inertial>
            <collision name="platform_collision">
                <geometry>
                    <box>
                        <size>3 3 0.2</size>
                    </box>
                </geometry>
                <surface>
                    <contact>
                        <ode>
                            <max_vel>100.0</max_vel>
                            <min_depth>0.001</min_depth>
                        </ode>
                    </contact>
                    <friction>
                        <ode>
                            <mu>1.0</mu>
                            <mu2>1.0</mu2>
                        </ode>
                    </friction>
                </surface>
            </collision>
            <visual name="platform_visual">
                <geometry>
                    <box>
                        <size>3 3 0.2</size>
                    </box>
                </geometry>
                <material>
                    <ambient>0.6 0.6 0.6 0.9</ambient>
                    <diffuse>0.6 0.6 0.6 0.9</diffuse>
                    <specular>0.3 0.3 0.3 0.9</specular>
                </material>
            </visual>
        </link>
    </model>

    <model name="prius_hybrid">
        <static>true</static>
        <pose>278.08 -134.22 2.86 0.02 0 0.97</pose>
        <link name="chassis">
            <inertial>
                <mass>1326.0</mass>
                <pose>0 -0.266 0.48 0 0 0</pose>
                <inertia>
                    <ixx>2581.13354740</ixx>
                    <ixy>0.0</ixy>
                    <iyy>591.30846112</iyy>
                    <ixz>0.0</ixz>
                    <iyz>0.0</iyz>
                    <izz>2681.95008628</izz>
                </inertia>
            </inertial>
            <visual name="chassis_visual">
                <geometry>
                    <mesh>
                        <uri>model://prius_hybrid/meshes/Hybrid.obj</uri>
                        <scale>0.01 0.01 0.01</scale>
                        <submesh>
                            <name>Hybrid</name>
                            <center>false</center>
                        </submesh>
                    </mesh>
                </geometry>
            </visual>
            <visual name="interior_visual">
                <geometry>
                    <mesh>
                        <uri>model://prius_hybrid/meshes/Hybrid.obj</uri>
                        <scale>0.01 0.01 0.01</scale>
                        <submesh>
                            <name>Hybrid_Interior</name>
                            <center>false</center>
                        </submesh>
                    </mesh>
                </geometry>
            </visual>
            <visual name="windows_visual">
                <geometry>
                    <mesh>
                        <uri>model://prius_hybrid/meshes/Hybrid.obj</uri>
                        <scale>0.01 0.01 0.01</scale>
                        <submesh>
                            <name>Hybrid_Windows</name>
                            <center>false</center>
                        </submesh>
                    </mesh>
                </geometry>
            </visual>
            <collision name="chassis">
                <pose>0.0 0.05 0.625 0 0 0</pose>
                <geometry>
                    <box>
                        <size>1.8 4.5 1.5</size>
                    </box>
                </geometry>
            </collision>
            <sensor name="back_camera_sensor" type="camera">
                <update_rate>60</update_rate>
                <topic>back_camera</topic>
                <camera name="back_camera">
                    <horizontal_fov>1.39626</horizontal_fov>
                    <image>
                        <width>800</width>
                        <height>800</height>
                        <format>R8G8B8</format>
                    </image>
                    <clip>
                        <near>0.02</near>
                        <far>300</far>
                    </clip>
                </camera>
                <pose>0 1.45 1.4 0 0.05 1.5707</pose>
            </sensor>
            <sensor name="front_camera_sensor" type="camera">
                <update_rate>60</update_rate>
                <topic>front_camera</topic>
                <camera name="front_camera">
                    <horizontal_fov>1.39626</horizontal_fov>
                    <image>
                        <width>800</width>
                        <height>800</height>
                        <format>R8G8B8</format>
                    </image>
                    <clip>
                        <near>0.02</near>
                        <far>300</far>
                    </clip>
                </camera>
                <pose>0 -0.4 1.4 0 0.05 -1.5707</pose>
            </sensor>
            <sensor name="left_camera_sensor" type="camera">
                <update_rate>60</update_rate>
                <topic>left_camera</topic>
                <camera name="left_camera">
                    <horizontal_fov>1.39626</horizontal_fov>
                    <image>
                        <width>800</width>
                        <height>800</height>
                        <format>R8G8B8</format>
                    </image>
                    <clip>
                        <near>0.02</near>
                        <far>300</far>
                    </clip>
                </camera>
                <pose>1 -0.7 1 0 0.05 1</pose>
            </sensor>
            <sensor name="right_camera_sensor" type="camera">
                <update_rate>60</update_rate>
                <topic>right_camera</topic>
                <camera name="right_camera">
                    <horizontal_fov>1.39626</horizontal_fov>
                    <image>
                        <width>800</width>
                        <height>800</height>
                        <format>R8G8B8</format>
                    </image>
                    <clip>
                        <near>0.02</near>
                        <far>300</far>
                    </clip>
                </camera>
                <pose>-1 -0.7 1 0 0.05 2.1416</pose>
            </sensor>
        </link>
        <link name="steering_wheel">
            <pose>0.357734 -0.627868 0.988243 -1.302101 0 0</pose>
            <inertial>
                <mass>1.0</mass>
                <inertia>
                    <ixx>0.14583300</ixx>
                    <ixy>0</ixy>
                    <ixz>0</ixz>
                    <iyy>0.14583300</iyy>
                    <iyz>0</iyz>
                    <izz>0.12500000</izz>
                </inertia>
            </inertial>
            <collision name="collision">
                <geometry>
                    <cylinder>
                        <radius>0.178172</radius>
                        <length>0.041845</length>
                    </cylinder>
                </geometry>
                <surface>
                    <contact>
                        <ode>
                            <min_depth>0.003</min_depth>
                        </ode>
                    </contact>
                </surface>
            </collision>
            <visual name="visual">
                <pose>0 0 0 1.302101 0 0</pose>
                <geometry>
                    <mesh>
                        <uri>model://prius_hybrid/meshes/Hybrid.obj</uri>
                        <scale>0.01 0.01 0.01</scale>
                        <submesh>
                            <name>Steering_Wheel</name>
                            <center>true</center>
                        </submesh>
                    </mesh>
                </geometry>
            </visual>
        </link>
        <link name="front_left_wheel">
            <pose>0.76 -1.41 0.3 0 0 0</pose>
            <inertial>
                <mass>11</mass>
                <inertia>
                    <ixx>0.58631238</ixx>
                    <ixy>0.0</ixy>
                    <iyy>0.33552910</iyy>
                    <ixz>0.0</ixz>
                    <iyz>0.0</iyz>
                    <izz>0.33552910</izz>
                </inertia>
            </inertial>
            <visual name="visual">
                <pose>0.04 0.0 0.0 0 0 0</pose>
                <geometry>
                    <mesh>
                        <uri>model://prius_hybrid/meshes/Hybrid.obj</uri>
                        <scale>0.01 0.01 0.01</scale>
                        <submesh>
                            <name>Wheel_Front_Left_</name>
                            <center>true</center>
                        </submesh>
                    </mesh>
                </geometry>
            </visual>
            <collision name="collision">
                <pose>0.0 0.0 0.0 0 1.5707963267948966 0</pose>
                <geometry>
                    <sphere>
                        <radius>0.31265</radius>
                    </sphere>
                </geometry>
                <surface>
                    <friction>
                        <ode>
                            <mu>0.9</mu>
                            <mu2>0.9</mu2>
                            <slip1>0.0</slip1>
                            <slip2>0.0</slip2>
                        </ode>
                    </friction>
                    <contact>
                        <ode>
                            <min_depth>0.001</min_depth>
                            <kp>1e9</kp>
                        </ode>
                    </contact>
                </surface>
            </collision>
        </link>
        <link name="front_right_wheel">
            <pose>-0.76 -1.41 0.3 0 0 0</pose>
            <inertial>
                <mass>11</mass>
                <inertia>
                    <ixx>0.58631238</ixx>
                    <ixy>0.0</ixy>
                    <iyy>0.33552910</iyy>
                    <ixz>0.0</ixz>
                    <iyz>0.0</iyz>
                    <izz>0.33552910</izz>
                </inertia>
            </inertial>
            <visual name="visual">
                <pose>-0.04 0.0 0.0 0 0 0</pose>
                <pose>0 0 0.0 0 0 0</pose>
                <geometry>
                    <mesh>
                        <uri>model://prius_hybrid/meshes/Hybrid.obj</uri>
                        <scale>0.01 0.01 0.01</scale>
                        <submesh>
                            <name>Wheel_Front_Right</name>
                            <center>true</center>
                        </submesh>
                    </mesh>
                </geometry>
            </visual>
            <collision name="collision">
                <pose>0.0 0.0 0.0 0 1.5707963267948966 0</pose>
                <geometry>
                    <sphere>
                        <radius>0.31265</radius>
                    </sphere>
                </geometry>
                <surface>
                    <friction>
                        <ode>
                            <mu>0.9</mu>
                            <mu2>0.9</mu2>
                            <slip1>0.0</slip1>
                            <slip2>0.0</slip2>
                        </ode>
                    </friction>
                    <contact>
                        <ode>
                            <min_depth>0.001</min_depth>
                            <kp>1e9</kp>
                        </ode>
                    </contact>
                </surface>
            </collision>
        </link>
        <link name="rear_left_wheel">
            <pose>0.786 1.45 0.3 0 0 0</pose>
            <inertial>
                <mass>11</mass>
                <inertia>
                    <ixx>0.58631238</ixx>
                    <ixy>0.0</ixy>
                    <iyy>0.33552910</iyy>
                    <ixz>0.0</ixz>
                    <iyz>0.0</iyz>
                    <izz>0.33552910</izz>
                </inertia>
            </inertial>
            <visual name="visual">
                <pose>0.04 0.0 0.0 0 0 0</pose>
                <geometry>
                    <mesh>
                        <uri>model://prius_hybrid/meshes/Hybrid.obj</uri>
                        <scale>0.01 0.01 0.01</scale>
                        <submesh>
                            <name>Wheel_Front_Left_</name>
                            <center>true</center>
                        </submesh>
                    </mesh>
                </geometry>
            </visual>
            <collision name="collision">
                <pose>0.0 0.0 0.0 0 1.5707963267948966 0</pose>
                <geometry>
                    <sphere>
                        <radius>0.31265</radius>
                    </sphere>
                </geometry>
                <surface>
                    <friction>
                        <ode>
                            <mu>1.1</mu>
                            <mu2>1.1</mu2>
                            <slip1>0.0</slip1>
                            <slip2>0.0</slip2>
                        </ode>
                    </friction>
                    <contact>
                        <ode>
                            <min_depth>0.001</min_depth>
                            <kp>1e9</kp>
                        </ode>
                    </contact>
                </surface>
            </collision>
        </link>
        <link name="rear_right_wheel">
            <pose>-0.786 1.45 0.3 0 0 0</pose>
            <inertial>
                <mass>11</mass>
                <inertia>
                    <ixx>0.58631238</ixx>
                    <ixy>0.0</ixy>
                    <iyy>0.33552910</iyy>
                    <ixz>0.0</ixz>
                    <iyz>0.0</iyz>
                    <izz>0.33552910</izz>
                </inertia>
            </inertial>
            <visual name="visual">
                <pose>-0.04 0.0 0.0 0 0 0</pose>
                <geometry>
                    <mesh>
                        <uri>model://prius_hybrid/meshes/Hybrid.obj</uri>
                        <scale>0.01 0.01 0.01</scale>
                        <submesh>
                            <name>Wheel_Front_Right</name>
                            <center>true</center>
                        </submesh>
                    </mesh>
                </geometry>
            </visual>
            <collision name="collision">
                <pose>0.0 0.0 0.0 0 1.5707963267948966 0</pose>
                <geometry>
                    <sphere>
                        <radius>0.31265</radius>
                    </sphere>
                </geometry>
                <surface>
                    <friction>
                        <ode>
                            <mu>1.1</mu>
                            <mu2>1.1</mu2>
                            <slip1>0.0</slip1>
                            <slip2>0.0</slip2>
                        </ode>
                    </friction>
                    <contact>
                        <ode>
                            <min_depth>0.001</min_depth>
                            <kp>1e9</kp>
                        </ode>
                    </contact>
                </surface>
            </collision>
        </link>
        <link name="rear_axle">
            <pose>0 1.45 0.3 0 0 0</pose>
            <inertial>
                <mass>30.0</mass>
                <inertia>
                    <ixx>0.08437499999999999</ixx>
                    <ixy>0.0</ixy>
                    <iyy>4.64581</iyy>
                    <ixz>0.0</ixz>
                    <iyz>0.0</iyz>
                    <izz>4.64581</izz>
                </inertia>
            </inertial>
            <visual name="visual">
                <pose>0.0 0.0 0.0 0 1.5707963267948966 0</pose>
                <geometry>
                    <cylinder>
                        <length>1.357</length>
                        <radius>0.075</radius>
                    </cylinder>
                </geometry>
                <material>
                    <script>
                        <name>Gazebo/Grey</name>
                        <uri>file://media/materials/scripts/gazebo.material</uri>
                    </script>
                </material>
            </visual>
        </link>
        <joint type="revolute" name="rear_axle_joint">
            <child>rear_axle</child>
            <parent>chassis</parent>
            <axis>
                <xyz>0 1 0</xyz>
                <limit>
                    <lower>-0.05089058524173028</lower>
                    <upper>0.05089058524173028</upper>
                </limit>
                <dynamics>
                    <spring_stiffness>20000.0</spring_stiffness>
                    <damping>2000.0</damping>
                </dynamics>
            </axis>
        </joint>
        <joint type="revolute" name="rear_left_wheel_joint">
            <child>rear_left_wheel</child>
            <parent>rear_axle</parent>
            <axis>
                <xyz>1 0 0</xyz>
                <dynamics>
                    <friction>12.031606150200002</friction>
                </dynamics>
            </axis>
        </joint>
        <joint type="revolute" name="rear_right_wheel_joint">
            <child>rear_right_wheel</child>
            <parent>rear_axle</parent>
            <axis>
                <xyz>1 0 0</xyz>
                <dynamics>
                    <friction>12.031606150200002</friction>
                </dynamics>
            </axis>
        </joint>
        <joint name="steering_joint" type="revolute">
            <pose>-0.002 0 0 0 0 0</pose>
            <parent>chassis</parent>
            <child>steering_wheel</child>
            <axis>
                <xyz>0 0.964095 0.265556</xyz>
                <limit>
                    <lower>-7.85</lower>
                    <upper>7.85</upper>
                </limit>
                <dynamics>
                    <damping>1.0</damping>
                </dynamics>
                <use_parent_model_frame>true</use_parent_model_frame>
            </axis>
            <physics>
                <ode>
                    <cfm_damping>1</cfm_damping>
                </ode>
            </physics>
        </joint>



<!-- from demo -->


      <link name="front_left_wheel_steering_link">
        <pose>0.76 -1.41 0.3 0 0 0</pose>
        <inertial>
          <mass>0.5</mass>
          <inertia>
            <ixx>0.0153</ixx>
            <iyy>0.025</iyy>
            <izz>0.0153</izz>
          </inertia>
        </inertial>
      </link>

      <link name="front_right_wheel_steering_link">
        <pose>-0.76 -1.41 0.3 0 0 0</pose>
        <inertial>
          <mass>0.5</mass>
          <inertia>
            <ixx>0.0153</ixx>
            <iyy>0.025</iyy>
            <izz>0.0153</izz>
          </inertia>
        </inertial>
      </link>

      <joint name="front_left_wheel_steering_joint" type="revolute">
        <child>front_left_wheel_steering_link</child>
        <parent>chassis</parent>
        <axis>
          <xyz>0 0 1</xyz>
          <limit>
            <lower>-0.8727</lower>
            <upper>0.8727</upper>
            <effort>1e6</effort>
          </limit>
          <use_parent_model_frame>1</use_parent_model_frame>
        </axis>
      </joint>

      <joint name="front_right_wheel_steering_joint" type="revolute">
        <parent>chassis</parent>
        <child>front_right_wheel_steering_link</child>
        <axis>
          <xyz>0 0 1</xyz>
          <limit>
            <lower>-0.8727</lower>
            <upper>0.8727</upper>
            <effort>1e6</effort>
          </limit>
        </axis>
      </joint>

      <joint name='front_left_wheel_joint' type='revolute'>
        <parent>front_left_wheel_steering_link</parent>
        <child>front_left_wheel</child>
        <axis>
          <xyz>1 0 0</xyz>
          <limit>
            <lower>-1.79769e+308</lower>
            <upper>1.79769e+308</upper>
          </limit>
          <dynamics>
            <friction>18.0474092253</friction>
          </dynamics>
        </axis>
      </joint>

      <joint name='front_right_wheel_joint' type='revolute'>
        <parent>front_right_wheel_steering_link</parent>
        <child>front_right_wheel</child>
        <axis>
          <xyz>1 0 0</xyz>
          <limit>
            <lower>-1.79769e+308</lower>
            <upper>1.79769e+308</upper>
          </limit>
          <dynamics>
            <friction>18.0474092253</friction>
          </dynamics>
        </axis>
      </joint>

        <plugin
          filename="ignition-gazebo-ackermann-steering-system"
          name="ignition::gazebo::systems::AckermannSteering">
          <topic>/cmd_vel</topic>
          <left_joint>front_left_wheel_joint</left_joint>
          <left_joint>rear_left_wheel_joint</left_joint>
          <right_joint>front_right_wheel_joint</right_joint>
          <right_joint>rear_right_wheel_joint</right_joint>
          <left_steering_joint>front_left_wheel_steering_joint</left_steering_joint>
          <right_steering_joint>front_right_wheel_steering_joint</right_steering_joint>
          <kingpin_width>1.0</kingpin_width>
          <steering_limit>0.5</steering_limit>
          <wheel_base>1.0</wheel_base>
          <wheel_separation>1.572</wheel_separation>
          <wheel_radius>0.31265</wheel_radius>
          <min_velocity>-10</min_velocity>
          <max_velocity>100</max_velocity>
          <min_acceleration>-30</min_acceleration>
          <max_acceleration>30</max_acceleration>
        </plugin>
    </model>
  </world>
</sdf>
